Workbook
Name ks_fee: Inputs!$B$4
Name pp_fee: Inputs!$B$5
Name pp_fix: Inputs!$B$6
Name drop_rate: Inputs!$B$7
Name payout_days: Inputs!$B$8
Name camp_days: Inputs!$B$11
Name launch_date: Inputs!$B$12
Name min_batch: Inputs!$B$13
Name p_support: Inputs!$B$16
Name p_fobkit: Inputs!$B$17
Name p_early: Inputs!$B$18
Name p_std: Inputs!$B$19
Name p_hose: Inputs!$B$20
Name ship_pump: Inputs!$B$21
Name ship_kit: Inputs!$B$22
Name ship_sup: Inputs!$B$23
Name cost_ship_pump: Inputs!$B$26
Name cost_ship_kit: Inputs!$B$27
Name cost_ship_sup: Inputs!$B$28
Name c_engine: Inputs!$B$31
Name c_pumpend: Inputs!$B$32
Name c_frame: Inputs!$B$33
Name c_remote: Inputs!$B$34
Name c_valve: Inputs!$B$35
Name c_power: Inputs!$B$36
Name c_labor: Inputs!$B$37
Name c_qc: Inputs!$B$38
Name c_pack: Inputs!$B$39
Name c_warr: Inputs!$B$40
Name c_hosepkg: Inputs!$B$41
Name c_kit: Inputs!$B$42
Name c_support: Inputs!$B$43
Name vol_disc: Inputs!$B$44
Name cost_over: Inputs!$B$45
Name o_insur: Inputs!$B$48
Name o_fcc: Inputs!$B$49
Name o_test: Inputs!$B$50
Name o_tool: Inputs!$B$51
Name o_video: Inputs!$B$52
Name o_legal: Inputs!$B$53
Name o_patent: Inputs!$B$54
Name o_ads: Inputs!$B$55
Name o_soft: Inputs!$B$56
Name contingency: Inputs!$B$57
Name tax_res: Inputs!$B$58
Name hrs_wk: Inputs!$B$68
Name hrs_unit: Inputs!$B$69
Name lead_eng: Inputs!$B$70
Name deposit_pct: Inputs!$B$71
Name unit_cost_base: Unit_Cost!$B$12
Name unit_cost_cons: Unit_Cost!$C$12
Name unit_cost_opt: Unit_Cost!$D$12

Sheet README
A1: Wildfire Watchdog — Dry Lightning 3000 Kickstarter Financial Model v1 (DRAFT for advisor review)
A2: Built 2026-09-17. All formulas are live. Change blue cells on the Inputs sheet only; every other sheet recalculates.
A4: Status labels used in column C of Inputs:
A5: VERIFIED = supported by a receipt, quote, signed document or measured test in the Wildfire Watchdog Drive records.
A6: ESTIMATE = founder or producer estimate with a stated basis and a low/high range (columns E and F).
A7: PROPOSED = a campaign design choice (price, quantity, policy) awaiting Jeremy's and the advisor's approval.
A8: UNKNOWN = no evidence yet; a placeholder that must be replaced before launch.
A10: Sheets:
A11: Inputs — every assumption (costs, fees, prices, quantities, timing).
A12: Unit_Cost — per-unit bill of materials for the DL3000 in three cost scenarios.
A13: Rewards — each reward tier: price, shipping, fees, per-unit cost, contribution margin.
A14: Scenarios — Conservative / Base / Optimistic backer mixes → gross pledges, fees, dropped pledges, net cash, costs, surplus.
... A22: Volume discounts on parts are MODELED (not quoted) and are labeled as such on Inputs.

Sheet Inputs
A1: Input | B1: Value | C1: Status | D1: Basis / source | E1: Low | F1: High
A3: A. Platform fees and collections
A4: Kickstarter platform fee (% of collected pledges) | B4: 0.05 | C4: VERIFIED | D4: Kickstarter fees page (US): 5% of funds collected on successful projects
A5: Payment processing fee (% of pledge) | B5: 0.03 | C5: VERIFIED | D5: Kickstarter fees page (US): 3% + $0.20 per pledge
A6: Payment processing fixed fee per pledge ($) | B6: 0.2 | C6: VERIFIED | D6: Kickstarter fees page (US)
A7: Dropped / failed pledges (% of pledged $) | B7: 0.03 | C7: ESTIMATE | D7: Typical reported range 1–5% for hardware; conservative 3% used | E7: 0.01 | F7: 0.05
A8: Days after campaign end until funds arrive | B8: 14 | C8: VERIFIED | D8: Kickstarter: funds transferred ~14 days after a successful campaign ends
A10: B. Campaign design (PROPOSED)
A11: Campaign length (days) | B11: 30 | C11: PROPOSED | D11: Kickstarter recommends 30 days or fewer; prelaunch page 4–6 weeks before
A12: Planned launch date | B12: 2027-01-19 | C12: PROPOSED | D12: After holidays, inside the Oct–Mar planning season, before Northern Tool listing; allows Jan demo video
A13: Minimum production batch the goal must fund (units) | B13: 10 | C13: PROPOSED | D13: Business plan (2026-09-15) sizes Kickstarter at 10–20 units; 10 = smallest sensible parts order | E13: 8 | F13: 15
A15: C. Reward prices and shipping (PROPOSED) — see Rewards sheet for inclusions
A16: Tier 1 — Supporter (decal + backer wall) price | B16: 35 | C16: PROPOSED | D16: Low tier for friends/family/community; keeps backer count and social proof up
A17: Tier 2 — Remote Control Kit (retrofit for Honda iGX390 electric-start pumps) price | B17: 1250 | C17: PROPOSED | D17: Harness + 2 rolling-code receivers + fob + relay/valve box; only for owners of a compatible pump (see compatibility note on Rewards) | E17: 995 | F17: 1495
A18: Tier 3 — DL3000 Early Bird price | B18: 4950 | C18: PROPOSED | D18: 10% below $5,500 target MSRP; rewards first movers without undercutting Northern Tool MAP long term | E18: 4750 | F18: 5100
A19: Tier 4 — DL3000 Kickstarter price | B19: 5250 | C19: PROPOSED | D19: ~4.5% below target MSRP $5,500 | E19: 5100 | F19: 5500
A20: Tier 5 — DL3000 + Hose & Nozzle Package price | B20: 5900 | C20: PROPOSED | D20: Pump + 2 in. discharge hose (50 ft), adjustable nozzle, suction hose, strainer, spare fob | E20: 5750 | F20: 6100
A21: Shipping charged to backer per pump (US contiguous, LTL freight to residential w/ liftgate) | B21: 349 | C21: ESTIMATE | D21: Palletized ~180 lb crate; LTL residential+liftgate quotes typically $250–$450 from Bend OR | E21: 250 | F21: 450
A22: Shipping charged per Remote Control Kit (UPS Ground) | B22: 25 | C22: ESTIMATE | D22: ~8 lb box | E22: 18 | F22: 35
A23: Shipping charged per Supporter tier (USPS) | B23: 0 | C23: PROPOSED | D23: Decal mailed first-class; cost absorbed
A25: D. Actual shipping cost paid by Wildfire Watchdog
A26: Actual freight cost per pump (crate + LTL residential + liftgate) | B26: 380 | C26: ESTIMATE | D26: Includes ~$60 crate materials; verify with 2 LTL quotes before launch | E26: 300 | F26: 500
A27: Actual shipping cost per kit | B27: 22 | C27: ESTIMATE | D27: UPS Ground 8 lb, box | E27: 15 | F27: 30
A28: Actual mailing cost per supporter reward | B28: 2.5 | C28: ESTIMATE | D28: First-class envelope + decal | E28: 1.5 | F28: 4
A30: E. Per-unit DL3000 parts (Base = 10-unit pricing). Volume discounts are MODELED, not quoted.
A31: Honda iGX390 electric-start engine (with 12V charging coil) | B31: 1150 | C31: ESTIMATE | D31: Retail iGX390 ES lists ~$1,100–$1,300 at US dealers; no dealer quote on file yet | E31: 1050 | F31: 1300
A32: High-pressure pump end (2 in./3 in., matched to iGX390) | B32: 260 | C32: ESTIMATE | D32: Business plan 2026-09-15 lists $130 imported at 50 units; single-unit purchase pricing is higher | E32: 130 | F32: 350
A33: Frame / skid / roll cage (steel, powder coat) | B33: 260 | C33: ESTIMATE | D33: Business plan: $220 at 50 units; small batch local fab higher | E33: 200 | F33: 350
A34: RF remote system: 2× Solidremote 202U kits (4 fobs), 3 relays, Deutsch 6-pin, fuses, wire, switches, enclosure | B34: 190 | C34: ESTIMATE | D34: Briefing 2026-09-10 parts list; business plan: $140 at 50 units | E34: 140 | F34: 240
A35: 2 in. 12V spring-return electric ball valve + float valve + camlock fittings | B35: 230 | C35: ESTIMATE | D35: Business plan: $180 at 50 units; spring-return actuators are the cost driver | E35: 180 | F35: 300
A36: 12V battery, USB power bank, solar maintainer, cabling | B36: 140 | C36: ESTIMATE | D36: Business plan: $120 at 50 units | E36: 100 | F36: 180
A37: Assembly + test labor per unit (hours × rate) | B37: 240 | C37: ESTIMATE | D37: ~6 h per unit in small batch (founder + helper) × $40/h loaded; business plan assumes 3 h subcontracted at 50+ | E37: 160 | F37: 320
A38: Quality check: wet test fuel, consumables, labels, manual printing | B38: 45 | C38: ESTIMATE | D38: Fuel for 30-min wet test, oil, warning labels, printed quick-start guide | E38: 30 | F38: 70
A39: Packaging: pallet, crate, straps, foam (excluding freight) | B39: 0 | C39: ESTIMATE | D39: Included in actual freight line above to avoid double counting
A40: Warranty reserve per pump (% of reward price basis, applied as $) | B40: 150 | C40: ESTIMATE | D40: ~3% of price, per business plan practice (3%) | E40: 100 | F40: 250
A41: Hose & Nozzle Package parts cost (2 in. × 50 ft hose, nozzle, suction hose, strainer, spare fob) | B41: 420 | C41: ESTIMATE | D41: Commodity fire hose $180–$250, nozzle $60–$120, suction kit $80–$120, fob $25 | E41: 340 | F41: 520
A42: Remote Control Kit parts cost (harness, 2 receivers, fob, relays, valve actuator, enclosure) + 2 h labor | B42: 470 | C42: ESTIMATE | D42: Remote parts $190 + valve actuator $180 + labor $80 + labels/manual $20 | E42: 380 | F42: 560
A43: Supporter reward cost (decal, printing) | B43: 3 | C43: ESTIMATE | D43: Vinyl decal $1–$2 + backer wall = website page | E43: 1 | F43: 5
A44: Modeled parts discount at 20+ units (%) | B44: 0.08 | C44: ESTIMATE | D44: MODELED, NOT QUOTED. Business plan shows ~15% from 50→150 units; 8% assumed for 10→20+ | E44: 0 | F44: 0.12
A45: Conservative scenario cost overrun (%) | B45: 0.15 | C45: ESTIMATE | D45: Stress factor applied to all parts + labor | E45: 0.1 | F45: 0.3
...

Sheet Unit_Cost
A1: DL3000 per-unit cost | B1: Base (10 units) | C1: Conservative (+overrun) | D1: Optimistic (20+ units, modeled discount) | E1: Notes
A2: Engine | B2: =c_engine | C2: =c_engine*(1+cost_over) | D2: =c_engine*(1-vol_disc)
A3: Pump end | B3: =c_pumpend | C3: =c_pumpend*(1+cost_over) | D3: =c_pumpend*(1-vol_disc)
A4: Frame / skid | B4: =c_frame | C4: =c_frame*(1+cost_over) | D4: =c_frame*(1-vol_disc)
A5: RF remote system | B5: =c_remote | C5: =c_remote*(1+cost_over) | D5: =c_remote*(1-vol_disc)
A6: Valve, float, camlock | B6: =c_valve | C6: =c_valve*(1+cost_over) | D6: =c_valve*(1-vol_disc)
A7: Battery / power | B7: =c_power | C7: =c_power*(1+cost_over) | D7: =c_power*(1-vol_disc)
A8: Assembly + test labor | B8: =c_labor | C8: =c_labor*(1+cost_over) | D8: =c_labor | E8: Labor/QC/warranty not discounted at volume
A9: QC consumables, labels, manual | B9: =c_qc | C9: =c_qc*(1+cost_over) | D9: =c_qc | E9: Labor/QC/warranty not discounted at volume
A10: Packaging (see freight) | B10: =c_pack | C10: =c_pack*(1+cost_over) | D10: =c_pack*(1-vol_disc)
A11: Warranty reserve | B11: =c_warr | C11: =c_warr*(1+cost_over) | D11: =c_warr | E11: Labor/QC/warranty not discounted at volume
A12: TOTAL per-unit cost (ex freight) | B12: =SUM(B2:B11) | C12: =SUM(C2:C11) | D12: =SUM(D2:D11)
A14: Reference: business plan 2026-09-15 estimated $1,700/unit at 50 units (NorthStar e420 engine) and line sheet 2026-08-25 stated ~$2,000 COGS (Honda iGX390). This model uses Honda iGX390 at 10-unit pricing, which is why Base is higher.

Sheet Rewards
A1: Tier | B1: Reward price | C1: Shipping charged | D1: Total pledge | E1: KS fee 5% | F1: Processing 3%+$0.20 | G1: Net cash to WW | H1: Reward cost (base) | I1: Actual shipping cost | J1: Contribution margin $ | K1: Margin % of net | L1: Qty cap | M1: Est. delivery
A2: T1 Supporter — decal, backer wall, updates | B2: =p_support | C2: =ship_sup | D2: =B2+C2 | E2: =D2*ks_fee | F2: =D2*pp_fee+pp_fix | G2: =D2-E2-F2 | H2: =c_support | I2: =cost_ship_sup | J2: =G2-H2-I2 | K2: =IF(G2=0,0,J2/G2) | L2: no cap | M2: Mar 2027
A3: T2 Remote Control Kit (Honda iGX390 electric-start retrofit) | B3: =p_fobkit | C3: =ship_kit | D3: =B3+C3 | E3: =D3*ks_fee | F3: =D3*pp_fee+pp_fix | G3: =D3-E3-F3 | H3: =c_kit | I3: =cost_ship_kit | J3: =G3-H3-I3 | K3: =IF(G3=0,0,J3/G3) | L3: 10 | M3: May 2027
A4: T3 DL3000 Early Bird | B4: =p_early | C4: =ship_pump | D4: =B4+C4 | E4: =D4*ks_fee | F4: =D4*pp_fee+pp_fix | G4: =D4-E4-F4 | H4: =unit_cost_base | I4: =cost_ship_pump | J4: =G4-H4-I4 | K4: =IF(G4=0,0,J4/G4) | L4: 10 | M4: Jun 2027
A5: T4 DL3000 Kickstarter price | B5: =p_std | C5: =ship_pump | D5: =B5+C5 | E5: =D5*ks_fee | F5: =D5*pp_fee+pp_fix | G5: =D5-E5-F5 | H5: =unit_cost_base | I5: =cost_ship_pump | J5: =G5-H5-I5 | K5: =IF(G5=0,0,J5/G5) | L5: 15 | M5: Jul 2027
A6: T5 DL3000 + Hose & Nozzle Package | B6: =p_hose | C6: =ship_pump | D6: =B6+C6 | E6: =D6*ks_fee | F6: =D6*pp_fee+pp_fix | G6: =D6-E6-F6 | H6: =unit_cost_base+c_hosepkg | I6: =cost_ship_pump | J6: =G6-H6-I6 | K6: =IF(G6=0,0,J6/G6) | L6: 10 | M6: Jul 2027
A8: Contribution margin = net cash after fees minus reward cost minus actual shipping. Dropped pledges are applied at the scenario level, not per tier. Shipping regions: contiguous US only (see reward structure document).
A9: Add-ons (PROPOSED, priced on Rewards doc): spare fob $45; 2nd 50 ft hose $220; extended 2-year warranty $350. Not included in scenario totals (upside only).

Sheet Scenarios
A1: Line | B1: Conservative | C1: Base | D1: Optimistic | E1: Notes
A2: Supporter backers | B2: =Inputs!E61 | C2: =Inputs!B61 | D2: =Inputs!F61
A3: Remote Control Kit backers | B3: =Inputs!E62 | C3: =Inputs!B62 | D3: =Inputs!F62
A4: DL3000 Early Bird backers | B4: =Inputs!E63 | C4: =Inputs!B63 | D4: =Inputs!F63
A5: DL3000 Kickstarter-price backers | B5: =Inputs!E64 | C5: =Inputs!B64 | D5: =Inputs!F64
A6: DL3000 + Hose backers | B6: =Inputs!E65 | C6: =Inputs!B65 | D6: =Inputs!F65
A7: Total pumps to build | B7: =B4+B5+B6 | C7: =C4+C5+C6 | D7: =D4+D5+D6
A8: Total backers (pledges) | B8: =B2+B3+B7 | C8: =C2+C3+C7 | D8: =D2+D3+D7
A10: Gross pledged (rewards + shipping) | B10: =B2*Rewards!$D$2+B3*Rewards!$D$3+B4*Rewards!$D$4+B5*Rewards!$D$5+B6*Rewards!$D$6 | C10: =C2*Rewards!$D$2+C3*Rewards!$D$3+C4*Rewards!$D$4+C5*Rewards!$D$5+C6*Rewards!$D$6 | D10: =D2*Rewards!$D$2+D3*Rewards!$D$3+D4*Rewards!$D$4+D5*Rewards!$D$5+D6*Rewards!$D$6
A11: of which shipping charged | B11: =B2*Rewards!$C$2+B3*Rewards!$C$3+(B7)*Rewards!$C$4 | C11: =C2*Rewards!$C$2+C3*Rewards!$C$3+(C7)*Rewards!$C$4 | D11: =D2*Rewards!$C$2+D3*Rewards!$C$3+(D7)*Rewards!$C$4
A12: Less dropped / failed pledges | B12: =-B10*drop_rate | C12: =-C10*drop_rate | D12: =-D10*drop_rate
A13: Collected pledges | B13: =B10+B12 | C13: =C10+C12 | D13: =D10+D12
A14: Less Kickstarter fee (5%) | B14: =-B13*ks_fee | C14: =-C13*ks_fee | D14: =-D13*ks_fee
A15: Less payment processing (3% + $0.20 × pledges) | B15: =-(B13*pp_fee+B8*(1-drop_rate)*pp_fix) | C15: =-(C13*pp_fee+C8*(1-drop_rate)*pp_fix) | D15: =-(D13*pp_fee+D8*(1-drop_rate)*pp_fix)
A16: NET CASH RECEIVED FROM KICKSTARTER | B16: =B13+B14+B15 | C16: =C13+C14+C15 | D16: =D13+D14+D15
A18: Per-unit cost used (DL3000) | B18: =unit_cost_cons | C18: =unit_cost_base | D18: =unit_cost_opt
A19: Pump build cost (units × per-unit) | B19: =B7*B18 | C19: =C7*C18 | D19: =D7*D18
A20: Hose package cost | B20: =B6*c_hosepkg*(1+cost_over) | C20: =C6*c_hosepkg | D20: =D6*c_hosepkg
A21: Remote Control Kit cost | B21: =B3*c_kit*(1+cost_over) | C21: =C3*c_kit | D21: =D3*c_kit
A22: Supporter reward cost | B22: =B2*c_support | C22: =C2*c_support | D22: =D2*c_support
A23: Actual freight & shipping cost | B23: =B7*cost_ship_pump+B3*cost_ship_kit+B2*cost_ship_sup | C23: =C7*cost_ship_pump+C3*cost_ship_kit+C2*cost_ship_sup | D23: =D7*cost_ship_pump+D3*cost_ship_kit+D2*cost_ship_sup
A24: Total per-unit (variable) costs | B24: =SUM(B19:B23) | C24: =SUM(C19:C23) | D24: =SUM(D19:D23)
A26: One-time costs (insurance, FCC SDoC, testing, tooling, video, legal, software) | B26: =o_insur+o_fcc+o_test+o_tool+o_video+o_legal+o_soft | C26: =o_insur+o_fcc+o_test+o_tool+o_video+o_legal+o_soft | D26: =o_insur+o_fcc+o_test+o_tool+o_video+o_legal+o_soft
A27: Optional advertising (separately costed) | B27: =o_ads | C27: =o_ads | D27: =o_ads
A28: Contingency | B28: =(B24+B26)*contingency | C28: =(C24+C26)*contingency | D28: =(D24+D26)*contingency
A29: TOTAL COST TO DELIVER | B29: =B24+B26+B27+B28 | C29: =C24+C26+C27+C28 | D29: =D24+D26+D27+D28
A31: SURPLUS / (SHORTFALL) before tax | B31: =B16-B29 | C31: =C16-C29 | D31: =D16-D29
A32: Income tax reserve on positive surplus | B32: =-MAX(0,B31)*tax_res | C32: =-MAX(0,C31)*tax_res | D32: =-MAX(0,D31)*tax_res
A33: Surplus after tax reserve (cash left for next batch / patent) | B33: =B31+B32 | C33: =C31+C32 | D33: =D31+D32
A34: Gross pledged vs funding goal (Funding_Goal!B12) | B34: =IF(B10>=Funding_Goal!$B$12,"FUNDED","NOT FUNDED") | C34: =IF(C10>=Funding_Goal!$B$12,"FUNDED","NOT FUNDED") | D34: =IF(D10>=Funding_Goal!$B$12,"FUNDED","NOT FUNDED")
A35: Note: If the Conservative scenario is NOT FUNDED, no money is collected and no rewards are owed — that is the Kickstarter all-or-nothing protection.

Sheet Funding_Goal
A1: Funding goal derivation | B1: Amount | C1: Notes
A2: Minimum production batch (units) | B2: =min_batch
A3: Per-unit cost, Base | B3: =unit_cost_base
A4: Per-unit actual freight | B4: =cost_ship_pump
A5: Variable cost of minimum batch | B5: =B2*(B3+B4)
A6: One-time costs required to deliver safely (insurance, FCC, testing, tooling, video, legal, software) | B6: =o_insur+o_fcc+o_test+o_tool+o_video+o_legal+o_soft
A7: Contingency | B7: =(B5+B6)*contingency
A8: Cash needed to deliver minimum batch | B8: =B5+B6+B7
A9: Effective take-home rate after fees and drops (from Base scenario) | B9: =Scenarios!C16/Scenarios!C10
A10: Gross pledges required = cash needed ÷ take-home rate | B10: =B8/B9
A11: Rounded up to nearest $1,000 | B11: =CEILING(B10,1000)
A12: RECOMMENDED FUNDING GOAL | B12: =B11 | C12: Set on Kickstarter as the all-or-nothing goal. It funds the minimum batch plus the one-time items; anything above it funds more units at better margins.
A14: Break-even backer counts
A15: Contribution margin per DL3000 (Kickstarter price tier, after fees, cost and freight) | B15: =Rewards!J5
A16: Contribution margin per Early Bird | B16: =Rewards!J4
A17: One-time costs + contingency on them | B17: =B6*(1+contingency)
A18: Pumps needed to cover one-time costs if all at Early Bird price | B18: =ROUNDUP(B17/B16,0)
A19: Pumps needed to cover one-time costs if all at Kickstarter price | B19: =ROUNDUP(B17/B15,0)
A20: Pumps needed to cover one-time costs + optional ads (Kickstarter price) | B20: =ROUNDUP((B17+o_ads)/B15,0)
A22: Reality check: goal ÷ average pump pledge (approx. pumps needed to hit goal) | B22: =ROUNDUP(B12/Rewards!D5,0)

Sheet Cash_Timing
A1: Month | B1: Phase | C1: Cash in | D1: Cash out | E1: Net | F1: Cumulative cash (Base) | G1: Notes
A2: 2026-10 | B2: Prelaunch prep | C2: =0 | D2: =o_video*0.5+o_soft*0.5 | E2: =C2-D2 | F2: =E2 | G2: Shoot photos; email tool; landing page (existing WordPress). No paid ads required.
A3: 2026-11 | B3: Prelaunch prep | C3: =0 | D3: =o_tool*0.5 | E3: =C3-D3 | F3: =F2+E3 | G3: Fixtures, crimp tooling, crate template. Insurance NOT yet bound (defer to campaign success or bind now if Northern Tool requires).
A4: 2026-12 | B4: Prelaunch page live | C4: =0 | D4: =o_video*0.5 | E4: =C4-D4 | F4: =F3+E4 | G4: Kickstarter prelaunch page; collect followers; finish demo video.
A5: 2027-01 | B5: Launch (Jan 19) | C5: =0 | D5: =o_ads*0.5 | E5: =C5-D5 | F5: =F4+E5 | G5: Optional ad test. Kickstarter collects pledges but pays nothing until ~14 days after end.
A6: 2027-02 | B6: Campaign ends (Feb 18); payout ~Mar 4 | C6: =0 | D6: =o_ads*0.5+o_insur*0.5 | E6: =C6-D6 | F6: =F5+E6 | G6: Bind insurance on success (Kinsale allows financing: ~$2,163 down). Order nothing until funded.
A7: 2027-03 | B7: Payout received; parts ordered | C7: =Scenarios!C16 | D7: =o_insur*0.5+o_fcc+o_test+o_legal+o_tool*0.5+Scenarios!C19*0.6 | E7: =C7-D7 | F7: =F6+E7 | G7: Engines, pump ends, frames ordered (60% of pump parts); FCC SDoC; test gear.
A8: 2027-04 | B8: Build batch 1 (Early Birds) | C8: =0 | D8: =Scenarios!C19*0.25+Scenarios!C21+Scenarios!C22 | E8: =C8-D8 | F8: =F7+E8 | G8: Kits and supporter rewards ship; first pumps in assembly.
A9: 2027-05 | B9: Build batch 2 | C9: =0 | D9: =Scenarios!C19*0.15+Scenarios!C20+Scenarios!C23*0.5 | E9: =C9-D9 | F9: =F8+E9 | G9: Early Bird pumps ship (freight).
A10: 2027-06 | B10: Ship remaining | C10: =0 | D10: =Scenarios!C23*0.5+o_soft*0.5 | E10: =C10-D10 | F10: =F9+E10 | G10: Remaining pumps and hose packages ship; support ramps.
A11: 2027-07 | B11: Close-out | C11: =0 | D11: =Scenarios!C28 | E11: =C11-D11 | F11: =F10+E11 | G11: Contingency drawn if needed; warranty reserve held.
A13: MINIMUM CASH JEREMY NEEDS BEFORE KICKSTARTER PAYS OUT (Base path) | F13: =-MIN(F2:F11)
A14: Lowest cumulative balance occurs before the March payout. This is the founder's out-of-pocket exposure if the campaign succeeds; if it fails, only prelaunch costs (video, tools, email tool) are spent.
A15: Supplier deposit modeled before payout (Inputs: deposit_pct × pump parts) | F15: =deposit_pct*Scenarios!C19
A16: Minimum cash including any modeled deposit | F16: =F13+F15

Sheet Stress_Tests
A1: Stress case (applied to Base scenario) | B1: Surplus before tax | C1: Change vs Base | D1: What it means
A2: Base scenario | B2: =Scenarios!C31 | C2: =B2-$B$2 | D2: Reference
A3: Parts + labor cost +15% | B3: =Scenarios!C31-Scenarios!C19*0.15-Scenarios!C20*0.15-Scenarios!C21*0.15 | C3: =B3-$B$2 | D3: Engine price rise or pump-end import surprise
A4: Parts + labor cost +30% | B4: =Scenarios!C31-Scenarios!C19*0.30-Scenarios!C20*0.30-Scenarios!C21*0.30 | C4: =B4-$B$2 | D4: Serious sourcing failure; still positive? check
A5: Freight +$150 per pump | B5: =Scenarios!C31-Scenarios!C7*150 | C5: =B5-$B$2 | D5: Residential LTL surcharges
A6: Dropped pledges 8% instead of 3% | B6: =Scenarios!C31-Scenarios!C10*0.05*(1-ks_fee-pp_fee) | C6: =B6-$B$2 | D6: Card failures on $5k pledges
A7: StarStone insurance ($10,598) instead of Kinsale | B7: =Scenarios!C31-(10598-o_insur) | C7: =B7-$B$2 | D7: If $2M/$4M limits are required by a retailer
A8: 3-month delay (extra software/support + storage $600/mo) | B8: =Scenarios!C31-1800 | C8: =B8-$B$2 | D8: Backer goodwill cost not modeled; update cadence matters more
A9: Only Early Birds sell (10 pumps, no T4/T5, no kits) | B9: =10*Rewards!J4+Inputs!B61*Rewards!J2-Scenarios!C26-Scenarios!C27-(10*(unit_cost_base+cost_ship_pump)+Scenarios!C26)*contingency | C9: =B9-$B$2 | D9: Worst funded mix
A10: Combined: cost +15% AND freight +$150 AND drops 8% | B10: =Scenarios!C31-Scenarios!C19*0.15-Scenarios!C20*0.15-Scenarios!C21*0.15-Scenarios!C7*150-Scenarios!C10*0.05*(1-ks_fee-pp_fee) | C10: =B10-$B$2 | D10: Compound bad year

Sheet Capacity
A1: Capacity check | B1: Value | C1: Notes
A2: Founder hours per week | B2: =hrs_wk
A3: Hours per pump | B3: =hrs_unit
A4: Pumps per week (founder only) | B4: =ROUNDDOWN(B2/B3,1)
A5: Pumps in Base scenario | B5: =Scenarios!C7
A6: Weeks to build Base scenario | B6: =ROUNDUP(B5/B4,0)
A7: Pumps in Optimistic scenario | B7: =Scenarios!D7
A8: Weeks to build Optimistic scenario | B8: =ROUNDUP(B7/B4,0)
A9: Engine/pump-end lead time (weeks) | B9: =lead_eng
A10: Weeks from payout to last shipment (Base) | B10: =B9+B6+1 | C10: +1 week for freight. Compare with promised delivery windows on Rewards.
A11: Weeks from payout to last shipment (Optimistic) | B11: =B9+B8+1
A13: HARD CAP recommended on pump rewards (all pump tiers combined) | B13: 35 | C13: Above ~35 pumps the founder-built model needs a helper or contract assembly; caps on Rewards enforce this (10 + 15 + 10).
